[2023-03-07 14:25:47,580] {taskinstance.py:1159} INFO - Dependencies all met for <TaskInstance: meu_primeiro_dag.Executando scheduled__2023-03-06T00:05:00+00:00 [queued]>
[2023-03-07 14:25:47,587] {taskinstance.py:1159} INFO - Dependencies all met for <TaskInstance: meu_primeiro_dag.Executando scheduled__2023-03-06T00:05:00+00:00 [queued]>
[2023-03-07 14:25:47,587] {taskinstance.py:1356} INFO - 
--------------------------------------------------------------------------------
[2023-03-07 14:25:47,588] {taskinstance.py:1357} INFO - Starting attempt 1 of 1
[2023-03-07 14:25:47,588] {taskinstance.py:1358} INFO - 
--------------------------------------------------------------------------------
[2023-03-07 14:25:47,604] {taskinstance.py:1377} INFO - Executing <Task(PythonOperator): Executando> on 2023-03-06 00:05:00+00:00
[2023-03-07 14:25:47,608] {standard_task_runner.py:52} INFO - Started process 62627 to run task
[2023-03-07 14:25:47,612] {standard_task_runner.py:79} INFO - Running: ['airflow', 'tasks', 'run', 'meu_primeiro_dag', 'Executando', 'scheduled__2023-03-06T00:05:00+00:00', '--job-id', '38', '--raw', '--subdir', 'DAGS_FOLDER/cotacao_dolar.py', '--cfg-path', '/tmp/tmpcw63fyx3', '--error-file', '/tmp/tmp74k5kq4d']
[2023-03-07 14:25:47,613] {standard_task_runner.py:80} INFO - Job 38: Subtask Executando
[2023-03-07 14:25:47,636] {task_command.py:370} INFO - Running <TaskInstance: meu_primeiro_dag.Executando scheduled__2023-03-06T00:05:00+00:00 [running]> on host veripc-System-Product-Name
[2023-03-07 14:25:47,666] {taskinstance.py:1569} INFO - Exporting the following env vars:
AIRFLOW_CTX_DAG_OWNER=airflow
AIRFLOW_CTX_DAG_ID=meu_primeiro_dag
AIRFLOW_CTX_TASK_ID=Executando
AIRFLOW_CTX_EXECUTION_DATE=2023-03-06T00:05:00+00:00
AIRFLOW_CTX_TRY_NUMBER=1
AIRFLOW_CTX_DAG_RUN_ID=scheduled__2023-03-06T00:05:00+00:00
[2023-03-07 14:25:47,667] {taskinstance.py:1889} ERROR - Task failed with exception
Traceback (most recent call last):
  File "/home/veri-pc/.local/lib/python3.10/site-packages/airflow/operators/python.py", line 171, in execute
    return_value = self.execute_callable()
  File "/home/veri-pc/.local/lib/python3.10/site-packages/airflow/operators/python.py", line 189, in execute_callable
    return self.python_callable(*self.op_args, **self.op_kwargs)
  File "/home/veri-pc/.local/lib/python3.10/site-packages/pymongo/collection.py", line 3207, in __call__
    raise TypeError(
TypeError: 'Collection' object is not callable. If you meant to call the 'cotacao' method on a 'Database' object it is failing because no such method exists.
[2023-03-07 14:25:47,670] {taskinstance.py:1395} INFO - Marking task as FAILED. dag_id=meu_primeiro_dag, task_id=Executando, execution_date=20230306T000500, start_date=20230307T172547, end_date=20230307T172547
[2023-03-07 14:25:47,676] {standard_task_runner.py:92} ERROR - Failed to execute job 38 for task Executando ('Collection' object is not callable. If you meant to call the 'cotacao' method on a 'Database' object it is failing because no such method exists.; 62627)
[2023-03-07 14:25:47,702] {local_task_job.py:156} INFO - Task exited with return code 1
[2023-03-07 14:25:47,713] {local_task_job.py:273} INFO - 0 downstream tasks scheduled from follow-on schedule check
