[2023-03-07 14:37:32,358] {taskinstance.py:1159} INFO - Dependencies all met for <TaskInstance: meu_primeiro_dag.retorna_cotacao scheduled__2023-03-06T01:01:00+00:00 [queued]>
[2023-03-07 14:37:32,362] {taskinstance.py:1159} INFO - Dependencies all met for <TaskInstance: meu_primeiro_dag.retorna_cotacao scheduled__2023-03-06T01:01:00+00:00 [queued]>
[2023-03-07 14:37:32,362] {taskinstance.py:1356} INFO - 
--------------------------------------------------------------------------------
[2023-03-07 14:37:32,362] {taskinstance.py:1357} INFO - Starting attempt 1 of 1
[2023-03-07 14:37:32,362] {taskinstance.py:1358} INFO - 
--------------------------------------------------------------------------------
[2023-03-07 14:37:32,373] {taskinstance.py:1377} INFO - Executing <Task(PythonOperator): retorna_cotacao> on 2023-03-06 01:01:00+00:00
[2023-03-07 14:37:32,375] {standard_task_runner.py:52} INFO - Started process 64338 to run task
[2023-03-07 14:37:32,377] {standard_task_runner.py:79} INFO - Running: ['airflow', 'tasks', 'run', 'meu_primeiro_dag', 'retorna_cotacao', 'scheduled__2023-03-06T01:01:00+00:00', '--job-id', '91', '--raw', '--subdir', 'DAGS_FOLDER/cotacao_dolar.py', '--cfg-path', '/tmp/tmpq1tovsi0', '--error-file', '/tmp/tmpqy789vr_']
[2023-03-07 14:37:32,377] {standard_task_runner.py:80} INFO - Job 91: Subtask retorna_cotacao
[2023-03-07 14:37:32,406] {task_command.py:370} INFO - Running <TaskInstance: meu_primeiro_dag.retorna_cotacao scheduled__2023-03-06T01:01:00+00:00 [running]> on host veripc-System-Product-Name
[2023-03-07 14:37:32,521] {taskinstance.py:1569} INFO - Exporting the following env vars:
AIRFLOW_CTX_DAG_OWNER=airflow
AIRFLOW_CTX_DAG_ID=meu_primeiro_dag
AIRFLOW_CTX_TASK_ID=retorna_cotacao
AIRFLOW_CTX_EXECUTION_DATE=2023-03-06T01:01:00+00:00
AIRFLOW_CTX_TRY_NUMBER=1
AIRFLOW_CTX_DAG_RUN_ID=scheduled__2023-03-06T01:01:00+00:00
[2023-03-07 14:37:32,521] {python.py:173} INFO - Done. Returned value was: <coroutine object Cotacao_dolar at 0x7fe807b78270>
[2023-03-07 14:37:32,523] {xcom.py:584} ERROR - Could not serialize the XCom value into JSON. If you are using pickle instead of JSON for XCom, then you need to enable pickle support for XCom in your airflow config.
[2023-03-07 14:37:32,523] {taskinstance.py:1889} ERROR - Task failed with exception
Traceback (most recent call last):
  File "/home/veri-pc/.local/lib/python3.10/site-packages/airflow/utils/session.py", line 68, in wrapper
    return func(*args, **kwargs)
  File "/home/veri-pc/.local/lib/python3.10/site-packages/airflow/models/taskinstance.py", line 2385, in xcom_push
    XCom.set(
  File "/home/veri-pc/.local/lib/python3.10/site-packages/airflow/utils/session.py", line 68, in wrapper
    return func(*args, **kwargs)
  File "/home/veri-pc/.local/lib/python3.10/site-packages/airflow/models/xcom.py", line 191, in set
    value = cls.serialize_value(
  File "/home/veri-pc/.local/lib/python3.10/site-packages/airflow/models/xcom.py", line 582, in serialize_value
    return json.dumps(value).encode('UTF-8')
  File "/usr/lib/python3.10/json/__init__.py", line 231, in dumps
    return _default_encoder.encode(obj)
  File "/usr/lib/python3.10/json/encoder.py", line 199, in encode
    chunks = self.iterencode(o, _one_shot=True)
  File "/usr/lib/python3.10/json/encoder.py", line 257, in iterencode
    return _iterencode(o, 0)
  File "/usr/lib/python3.10/json/encoder.py", line 179, in default
    raise TypeError(f'Object of type {o.__class__.__name__} '
TypeError: Object of type coroutine is not JSON serializable
[2023-03-07 14:37:32,525] {taskinstance.py:1395} INFO - Marking task as FAILED. dag_id=meu_primeiro_dag, task_id=retorna_cotacao, execution_date=20230306T010100, start_date=20230307T173732, end_date=20230307T173732
[2023-03-07 14:37:32,531] {standard_task_runner.py:92} ERROR - Failed to execute job 91 for task retorna_cotacao (Object of type coroutine is not JSON serializable; 64338)
[2023-03-07 14:37:32,549] {local_task_job.py:156} INFO - Task exited with return code 1
[2023-03-07 14:37:32,562] {local_task_job.py:273} INFO - 0 downstream tasks scheduled from follow-on schedule check
[2023-03-07 14:37:32,571] {dagrun.py:547} ERROR - Marking run <DagRun meu_primeiro_dag @ 2023-03-06 01:01:00+00:00: scheduled__2023-03-06T01:01:00+00:00, externally triggered: False> failed
[2023-03-07 14:37:32,572] {dagrun.py:607} INFO - DagRun Finished: dag_id=meu_primeiro_dag, execution_date=2023-03-06 01:01:00+00:00, run_id=scheduled__2023-03-06T01:01:00+00:00, run_start_date=2023-03-07 17:37:19.191030+00:00, run_end_date=2023-03-07 17:37:32.572159+00:00, run_duration=13.381129, state=failed, external_trigger=False, run_type=scheduled, data_interval_start=2023-03-06 01:01:00+00:00, data_interval_end=2023-03-06 01:02:00+00:00, dag_hash=d6c0371b760c0f4859c0257012b9f505
